<sdf version='1.7'>
  <world name='default'>
    <light name='sun' type='directional'>
      <cast_shadows>1</cast_shadows>
      <pose>0 0 10 0 -0 0</pose>
      <diffuse>0.8 0.8 0.8 1</diffuse>
      <specular>0.2 0.2 0.2 1</specular>
      <attenuation>
        <range>1000</range>
        <constant>0.9</constant>
        <linear>0.01</linear>
        <quadratic>0.001</quadratic>
      </attenuation>
      <direction>-0.5 0.1 -0.9</direction>
      <spot>
        <inner_angle>0</inner_angle>
        <outer_angle>0</outer_angle>
        <falloff>0</falloff>
      </spot>
    </light>
    <model name='ground_plane'>
      <static>1</static>
      <link name='link'>
        <collision name='collision'>
          <geometry>
            <plane>
              <normal>0 0 1</normal>
              <size>100 100</size>
            </plane>
          </geometry>
          <surface>
            <contact>
              <collide_bitmask>65535</collide_bitmask>
              <ode/>
            </contact>
            <friction>
              <ode>
                <mu>100</mu>
                <mu2>50</mu2>
              </ode>
              <torsional>
                <ode/>
              </torsional>
            </friction>
            <bounce/>
          </surface>
          <max_contacts>10</max_contacts>
        </collision>
        <visual name='visual'>
          <cast_shadows>0</cast_shadows>
          <geometry>
            <plane>
              <normal>0 0 1</normal>
              <size>100 100</size>
            </plane>
          </geometry>
          <material>
            <script>
              <uri>file://media/materials/scripts/gazebo.material</uri>
              <name>Gazebo/Grey</name>
            </script>
          </material>
        </visual>
        <self_collide>0</self_collide>
        <enable_wind>0</enable_wind>
        <kinematic>0</kinematic>
      </link>
    </model>
    <gravity>0 0 -9.8</gravity>
    <magnetic_field>6e-06 2.3e-05 -4.2e-05</magnetic_field>
    <atmosphere type='adiabatic'/>
    <physics type='ode'>
      <max_step_size>0.001</max_step_size>
      <real_time_factor>1</real_time_factor>
      <real_time_update_rate>1000</real_time_update_rate>
    </physics>
    <scene>
      <ambient>0.4 0.4 0.4 1</ambient>
      <background>0.7 0.7 0.7 1</background>
      <shadows>1</shadows>
    </scene>
    <audio>
      <device>default</device>
    </audio>
    <wind/>
    <spherical_coordinates>
      <surface_model>EARTH_WGS84</surface_model>
      <latitude_deg>0</latitude_deg>
      <longitude_deg>0</longitude_deg>
      <elevation>0</elevation>
      <heading_deg>0</heading_deg>
    </spherical_coordinates>
    <state world_name='default'>
      <sim_time>2005 553000000</sim_time>
      <real_time>197 505962472</real_time>
      <wall_time>1740521221 556351245</wall_time>
      <iterations>188695</iterations>
      <model name='go2'>
        <pose>0.268212 -2.87637 0.215412 0.002206 -0.011645 -1.00329</pose>
        <scale>1 1 1</scale>
        <link name='base_link'>
          <pose>0.268212 -2.87637 0.215412 0.002206 -0.011645 -1.00329</pose>
          <velocity>0.047748 -0.04792 0.048434 0.019375 0.038885 0.030675</velocity>
          <acceleration>-0.966174 -2.30435 -0.780012 -1.90618 -0.95182 0.431698</acceleration>
          <wrench>-6.78448 -16.1811 -5.47725 0 -0 0</wrench>
        </link>
        <link name='lf_hip_link'>
          <pose>0.411374 -3.01444 0.217767 0.018838 -0.011645 -1.00327</pose>
          <velocity>0.052086 -0.043554 0.040258 0.095973 -0.081641 0.02477</velocity>
          <acceleration>-0.112557 -1.2085 1.84044 -2.52913 0.404095 -0.582373</acceleration>
          <wrench>-0.076314 -0.819362 1.24782 0 -0 0</wrench>
        </link>
        <link name='lf_lower_leg_link'>
          <pose>0.396148 -2.80909 0.107828 0.04041 -1.08115 -1.03877</pose>
          <velocity>0.170653 -0.201964 -0.272603 2.52589 1.56198 0.106914</velocity>
          <acceleration>31.2655 13.5181 -157.827 -2.53779 1.46425 3.08737</acceleration>
          <wrench>6.69082 2.89288 -33.775 0 -0 0</wrench>
        </link>
        <link name='lf_upper_leg_link'>
          <pose>0.491878 -2.9631 0.219565 0.035893 1.01817 -0.972495</pose>
          <velocity>0.050206 -0.040845 0.052568 -1.44755 -1.0655 -0.010283</velocity>
          <acceleration>4.7752 -4.74582 0.914855 -2.25084 0.610321 -1.27962</acceleration>
          <wrench>5.50103 -5.46718 1.05391 0 -0 0</wrench>
        </link>
        <link name='lh_hip_link'>
          <pose>0.20347 -2.6883 0.213261 0.038969 -0.011654 -1.00318</pose>
          <velocity>0.041785 -0.049868 0.054872 -0.249028 0.463551 0.003855</velocity>
          <acceleration>-3.11954 -3.07568 2.96654 2.07355 -0.419654 -2.03971</acceleration>
          <wrench>-2.11505 -2.08531 2.01132 0 -0 0</wrench>
        </link>
        <link name='lh_lower_leg_link'>
          <pose>0.190729 -2.48273 0.103412 0.090284 -1.10346 -1.08386</pose>
          <velocity>0.082972 -0.205567 -0.240905 -0.13884 0.181532 -2.86439</velocity>
          <acceleration>20.0074 7.88596 -158.444 1.25411 -0.970056 -0.021555</acceleration>
          <wrench>4.28159 1.6876 -33.9069 0 -0 0</wrench>
        </link>
        <link name='lh_upper_leg_link'>
          <pose>0.283918 -2.63697 0.216962 0.07297 1.00688 -0.941</pose>
          <velocity>0.041501 -0.046004 0.009305 -1.4442 -0.296371 -0.057233</velocity>
          <acceleration>0.972281 -6.88979 -2.05982 2.40921 -1.36151 1.72602</acceleration>
          <wrench>1.12007 -7.93704 -2.37291 0 -0 0</wrench>
        </link>
        <link name='rf_hip_link'>
          <pose>0.332954 -3.06444 0.217561 -0.018845 -0.01164 -1.00338</pose>
          <velocity>0.05361 -0.04596 0.04246 0.173356 -0.204445 0.047402</velocity>
          <acceleration>0.588919 -2.06995 -4.44573 -2.05041 -0.5034 -0.951483</acceleration>
          <wrench>0.399287 -1.40343 -3.01421 0 -0 0</wrench>
        </link>
        <link name='rf_lower_leg_link'>
          <pose>0.153803 -2.96491 0.105807 -0.043962 -1.09461 -0.964129</pose>
          <velocity>0.055311 -0.006398 0.074978 0.809677 -0.036933 -0.027302</velocity>
          <acceleration>11.1905 34.3046 -34.8554 -2.00242 -1.56729 -0.343662</acceleration>
          <wrench>2.39476 7.34119 -7.45905 0 -0 0</wrench>
        </link>
        <link name='rf_upper_leg_link'>
          <pose>0.252429 -3.11575 0.219344 -0.035351 1.00819 -1.03353</pose>
          <velocity>0.054773 -0.048687 0.019432 0.408771 -0.055924 0.045169</velocity>
          <acceleration>2.17933 -1.64738 -12.8205 1.44505 1.23445 0.144967</acceleration>
          <wrench>2.51059 -1.89778 -14.7693 0 -0 0</wrench>
        </link>
        <link name='rh_hip_link'>
          <pose>0.125049 -2.73829 0.213058 -0.025471 -0.011643 -1.00327</pose>
          <velocity>0.043481 -0.052267 0.056596 0.290454 -0.386835 0.034356</velocity>
          <acceleration>-2.52234 -3.88033 -3.36209 1.17264 1.47557 2.57961</acceleration>
          <wrench>-1.71015 -2.63086 -2.27949 0 -0 0</wrench>
        </link>
        <link name='rh_lower_leg_link'>
          <pose>-0.053608 -2.64107 0.098527 -0.062049 -1.13349 -0.947242</pose>
          <velocity>0.048127 0.034999 0.122142 1.17099 0.071583 0.001337</velocity>
          <acceleration>4.8456 58.7046 -46.2243 -1.37126 -0.192135 -0.734255</acceleration>
          <wrench>1.03696 12.5628 -9.89199 0 -0 0</wrench>
        </link>
        <link name='rh_upper_leg_link'>
          <pose>0.044532 -2.78959 0.215481 -0.046262 0.988814 -1.04227</pose>
          <velocity>0.044148 -0.054962 0.012 0.784095 -0.059978 0.023354</velocity>
          <acceleration>-1.76334 -0.709352 -13.6424 0.786986 -0.01871 1.13265</acceleration>
          <wrench>-2.03136 -0.817173 -15.716 0 -0 0</wrench>
        </link>
      </model>
      <model name='ground_plane'>
        <pose>0 0 0 0 -0 0</pose>
        <scale>1 1 1</scale>
        <link name='link'>
          <pose>0 0 0 0 -0 0</pose>
          <velocity>0 0 0 0 -0 0</velocity>
          <acceleration>0 0 0 0 -0 0</acceleration>
          <wrench>0 0 0 0 -0 0</wrench>
        </link>
      </model>
      <model name='unit_box'>
        <pose>-2.445 3.27445 0.5 0 1e-06 -0.001485</pose>
        <scale>1 16.1104 1</scale>
        <link name='link'>
          <pose>-2.445 3.27445 0.5 0 1e-06 -0.001485</pose>
          <velocity>0 0 0 0 -0 0</velocity>
          <acceleration>-6.20696 -0.136344 8.01924 0.29838 -1.12312 -0.091713</acceleration>
          <wrench>-6.20696 -0.136344 8.01924 0 -0 0</wrench>
        </link>
      </model>
      <model name='unit_box_0'>
        <pose>-3.22399 4.7135 0.5 0 0 -0.004641</pose>
        <scale>0.558232 1 1</scale>
        <link name='link'>
          <pose>-3.22399 4.7135 0.5 0 0 -0.004641</pose>
          <velocity>0 0 0 0 -0 0</velocity>
          <acceleration>-1.69269 3.55114 4.49772 2.32244 0.243717 3.14152</acceleration>
          <wrench>-1.69269 3.55114 4.49772 0 -0 0</wrench>
        </link>
      </model>
      <model name='unit_box_4'>
        <pose>-2.38139 -3.13098 0.298287 0 -1e-05 -5.8e-05</pose>
        <scale>1 0.730235 1.18789</scale>
        <link name='link'>
          <pose>-2.38139 -3.13098 0.298287 0 -1e-05 -5.8e-05</pose>
          <velocity>0 0 0 0 -0 0</velocity>
          <acceleration>-0.094353 -0.012892 -9.66546 0.046465 -0.234751 -0.006007</acceleration>
          <wrench>-0.094353 -0.012892 -9.66546 0 -0 0</wrench>
        </link>
      </model>
      <model name='unit_cylinder'>
        <pose>2.62583 2.979 0.499992 -3e-06 2e-06 0.008394</pose>
        <scale>1 1 1</scale>
        <link name='link'>
          <pose>2.62583 2.979 0.499992 -3e-06 2e-06 0.008394</pose>
          <velocity>0 0 0 0 -0 0</velocity>
          <acceleration>0 0 -9.8 0 -0 0</acceleration>
          <wrench>0 0 -9.8 0 -0 0</wrench>
        </link>
      </model>
      <model name='unit_cylinder_1_clone'>
        <pose>2.58528 -4.38829 0.499995 -5e-06 -5e-06 -4.3e-05</pose>
        <scale>0.775649 0.775649 1</scale>
        <link name='link'>
          <pose>2.58528 -4.38829 0.499995 -5e-06 -5e-06 -4.3e-05</pose>
          <velocity>0 0 0 0 -0 0</velocity>
          <acceleration>0 0 -9.8 0 -0 0</acceleration>
          <wrench>0 0 -9.8 0 -0 0</wrench>
        </link>
      </model>
      <model name='unit_sphere_0'>
        <pose>3.57281 3.32459 0.5 -0.006427 0.015395 -0.002755</pose>
        <scale>1 1 1</scale>
        <link name='link'>
          <pose>3.57281 3.32459 0.5 -0.006427 0.015395 -0.002755</pose>
          <velocity>0 0 0 0 -0 0</velocity>
          <acceleration>0 0 0 0 -0 0</acceleration>
          <wrench>0 0 0 0 -0 0</wrench>
        </link>
      </model>
      <light name='sun'>
        <pose>0 0 10 0 -0 0</pose>
      </light>
    </state>
    <gui fullscreen='0'>
      <camera name='user_camera'>
        <pose>0.266285 12.8563 9.34167 0 0.772555 -1.72271</pose>
        <view_controller>orbit</view_controller>
        <projection_type>perspective</projection_type>
      </camera>
    </gui>
    <model name='unit_box_4'>
      <pose>-2.38145 -3.13109 0.5 0 -0 0</pose>
      <link name='link'>
        <inertial>
          <mass>1</mass>
          <inertia>
            <ixx>0.166667</ixx>
            <ixy>0</ixy>
            <ixz>0</ixz>
            <iyy>0.166667</iyy>
            <iyz>0</iyz>
            <izz>0.166667</izz>
          </inertia>
          <pose>0 0 0 0 -0 0</pose>
        </inertial>
        <collision name='collision'>
          <geometry>
            <box>
              <size>1 3.5168 0.502222</size>
            </box>
          </geometry>
          <max_contacts>10</max_contacts>
          <surface>
            <contact>
              <ode/>
            </contact>
            <bounce/>
            <friction>
              <torsional>
                <ode/>
              </torsional>
              <ode/>
            </friction>
          </surface>
        </collision>
        <visual name='visual'>
          <geometry>
            <box>
              <size>1 3.5168 0.502222</size>
            </box>
          </geometry>
          <material>
            <script>
              <name>Gazebo/Grey</name>
              <uri>file://media/materials/scripts/gazebo.material</uri>
            </script>
          </material>
        </visual>
        <self_collide>0</self_collide>
        <enable_wind>0</enable_wind>
        <kinematic>0</kinematic>
      </link>
    </model>
    <model name='unit_cylinder_1_clone'>
      <pose>1.76882 -4.38871 0.5 0 -0 0</pose>
      <link name='link'>
        <inertial>
          <mass>1</mass>
          <inertia>
            <ixx>0.145833</ixx>
            <ixy>0</ixy>
            <ixz>0</ixz>
            <iyy>0.145833</iyy>
            <iyz>0</iyz>
            <izz>0.125</izz>
          </inertia>
          <pose>0 0 0 0 -0 0</pose>
        </inertial>
        <collision name='collision'>
          <geometry>
            <cylinder>
              <radius>1.38137</radius>
              <length>1</length>
            </cylinder>
          </geometry>
          <max_contacts>10</max_contacts>
          <surface>
            <contact>
              <ode/>
            </contact>
            <bounce/>
            <friction>
              <torsional>
                <ode/>
              </torsional>
              <ode/>
            </friction>
          </surface>
        </collision>
        <visual name='visual'>
          <geometry>
            <cylinder>
              <radius>1.38137</radius>
              <length>1</length>
            </cylinder>
          </geometry>
          <material>
            <script>
              <name>Gazebo/Grey</name>
              <uri>file://media/materials/scripts/gazebo.material</uri>
            </script>
          </material>
        </visual>
        <self_collide>0</self_collide>
        <enable_wind>0</enable_wind>
        <kinematic>0</kinematic>
      </link>
    </model>
    <model name='go2'>
      <link name='base_link'>
        <inertial>
          <pose>0.023657 0 -0.003865 0 -0 0</pose>
          <mass>7.022</mass>
          <inertia>
            <ixx>0.0257344</ixx>
            <ixy>0.00012166</ixy>
            <ixz>-0.000373034</ixz>
            <iyy>0.10254</iyy>
            <iyz>-3.12e-05</iyz>
            <izz>0.110368</izz>
          </inertia>
        </inertial>
        <collision name='base_link_fixed_joint_lump__trunk_collision'>
          <pose>0 0 0 0 -0 0</pose>
          <geometry>
            <box>
              <size>0.3762 0.0935 0.114</size>
            </box>
          </geometry>
          <surface>
            <contact>
              <ode>
                <kp>10000</kp>
                <kd>1</kd>
              </ode>
            </contact>
            <friction>
              <ode>
                <mu>0.2</mu>
                <mu2>0.2</mu2>
              </ode>
              <torsional>
                <ode/>
              </torsional>
            </friction>
            <bounce/>
          </surface>
          <max_contacts>10</max_contacts>
        </collision>
        <collision name='base_link_fixed_joint_lump__imu_link_collision_1'>
          <pose>0 0 0 0 -0 0</pose>
          <geometry>
            <box>
              <size>0.001 0.001 0.001</size>
            </box>
          </geometry>
          <surface>
            <contact>
              <ode/>
            </contact>
            <friction>
              <ode/>
              <torsional>
                <ode/>
              </torsional>
            </friction>
            <bounce/>
          </surface>
          <max_contacts>10</max_contacts>
        </collision>
        <visual name='base_link_visual'>
          <pose>0 0 0 0 -0 0</pose>
          <geometry>
            <box>
              <size>0.001 0.001 0.001</size>
            </box>
          </geometry>
        </visual>
        <visual name='base_link_fixed_joint_lump__trunk_visual_1'>
          <pose>0 0 0 0 -0 0</pose>
          <geometry>
            <mesh>
              <scale>1 1 1</scale>
              <uri>file:///usr/app/comp0244_ws/comp0244-go2/install/go2_description/share/go2_description/meshes/trunk.dae</uri>
            </mesh>
          </geometry>
        </visual>
        <visual name='base_link_fixed_joint_lump__imu_link_visual_2'>
          <pose>0 0 0 0 -0 0</pose>
          <geometry>
            <box>
              <size>0.001 0.001 0.001</size>
            </box>
          </geometry>
        </visual>
        <visual name='base_link_fixed_joint_lump__livox_visual_3'>
          <pose>0.2 0 0.1 0 -0 0</pose>
          <geometry>
            <box>
              <size>0.1 0.06 0.06</size>
            </box>
          </geometry>
        </visual>
        <sensor name='imu_sensor' type='imu'>
          <always_on>1</always_on>
          <update_rate>100</update_rate>
          <imu>
            <angular_velocity>
              <x>
                <noise type='gaussian'>
                  <mean>0</mean>
                  <stddev>0.0002</stddev>
                </noise>
              </x>
              <y>
                <noise type='gaussian'>
                  <mean>0</mean>
                  <stddev>0.0002</stddev>
                </noise>
              </y>
              <z>
                <noise type='gaussian'>
                  <mean>0</mean>
                  <stddev>0.0002</stddev>
                </noise>
              </z>
            </angular_velocity>
            <linear_acceleration>
              <x>
                <noise type='gaussian'>
                  <mean>0</mean>
                  <stddev>0.017</stddev>
                </noise>
              </x>
              <y>
                <noise type='gaussian'>
                  <mean>0</mean>
                  <stddev>0.017</stddev>
                </noise>
              </y>
              <z>
                <noise type='gaussian'>
                  <mean>0</mean>
                  <stddev>0.017</stddev>
                </noise>
              </z>
            </linear_acceleration>
          </imu>
          <plugin name='imu_plugin' filename='libgazebo_ros_imu_sensor.so'>
            <ros>
              <namespace>imu</namespace>
              <remapping>~/out:=data</remapping>
            </ros>
            <initial_orientation_as_reference>0</initial_orientation_as_reference>
          </plugin>
          <pose>0 0 0 0 -0 0</pose>
        </sensor>
        <sensor name='livox' type='ray'>
          <visualize>1</visualize>
          <update_rate>10</update_rate>
          <plugin name='livox_plugin' filename='libros2_livox.so'>
            <ray>
              <scan>
                <horizontal>
                  <samples>100</samples>
                  <resolution>1</resolution>
                  <min_angle>0</min_angle>
                  <max_angle>6.2831852</max_angle>
                </horizontal>
                <vertical>
                  <samples>360</samples>
                  <resolution>1</resolution>
                  <min_angle>-0.12601276984444446</min_angle>
                  <max_angle>0.9637707965111111</max_angle>
                </vertical>
              </scan>
              <range>
                <min>0.1</min>
                <max>100.0</max>
                <resolution>0.002</resolution>
              </range>
              <noise>
                <type>gaussian</type>
                <mean>0.0</mean>
                <stddev>0.01</stddev>
              </noise>
            </ray>
            <visualize>1</visualize>
            <samples>20000</samples>
            <downsample>10</downsample>
            <csv_file_name>/usr/app/comp0244_ws/comp0244-go2/install/ros2_livox_simulation/share/ros2_livox_simulation/scan_mode/mid360.csv</csv_file_name>
            <topic>mid360</topic>
          </plugin>
          <pose>0.2 0 0.1 0 -0 0</pose>
          <ray>
            <scan>
              <horizontal>
                <samples>640</samples>
                <resolution>1</resolution>
                <min_angle>0</min_angle>
                <max_angle>0</max_angle>
              </horizontal>
              <vertical>
                <samples>1</samples>
                <min_angle>0</min_angle>
                <max_angle>0</max_angle>
              </vertical>
            </scan>
            <range>
              <min>0</min>
              <max>0</max>
            </range>
          </ray>
        </sensor>
        <self_collide>0</self_collide>
        <enable_wind>0</enable_wind>
        <kinematic>0</kinematic>
      </link>
      <joint name='lf_hip_joint' type='revolute'>
        <pose relative_to='base_link'>0.1934 0.0465 0 0 -0 0</pose>
        <parent>base_link</parent>
        <child>lf_hip_link</child>
        <axis>
          <xyz>1 0 0</xyz>
          <limit>
            <lower>-1.0472</lower>
            <upper>1.0472</upper>
            <effort>23.7</effort>
            <velocity>30.1</velocity>
          </limit>
          <dynamics>
            <damping>0.01</damping>
            <friction>0.2</friction>
            <spring_reference>0</spring_reference>
            <spring_stiffness>0</spring_stiffness>
          </dynamics>
        </axis>
      </joint>
      <link name='lf_hip_link'>
        <pose relative_to='lf_hip_joint'>0 0 0 0 -0 0</pose>
        <inertial>
          <pose>-0.0054 0.00194 -0.000105 0 -0 0</pose>
          <mass>0.678</mass>
          <inertia>
            <ixx>0.00048</ixx>
            <ixy>-3.01e-06</ixy>
            <ixz>1.11e-06</ixz>
            <iyy>0.000884</iyy>
            <iyz>-1.42e-06</iyz>
            <izz>0.000596</izz>
          </inertia>
        </inertial>
        <collision name='lf_hip_link_collision'>
          <pose>0 0.0955 0 1.5708 -0 0</pose>
          <geometry>
            <cylinder>
              <length>0.04</length>
              <radius>0.046</radius>
            </cylinder>
          </geometry>
          <surface>
            <contact>
              <ode/>
            </contact>
            <friction>
              <ode>
                <mu>0.2</mu>
                <mu2>0.2</mu2>
              </ode>
              <torsional>
                <ode/>
              </torsional>
            </friction>
            <bounce/>
          </surface>
          <max_contacts>10</max_contacts>
        </collision>
        <visual name='lf_hip_link_visual'>
          <pose>0 0 0 0 -0 0</pose>
          <geometry>
            <mesh>
              <scale>1 1 1</scale>
              <uri>file:///usr/app/comp0244_ws/comp0244-go2/install/go2_description/share/go2_description/meshes/hip.dae</uri>
            </mesh>
          </geometry>
        </visual>
        <self_collide>0</self_collide>
        <enable_wind>0</enable_wind>
        <kinematic>0</kinematic>
      </link>
      <joint name='lf_upper_leg_joint' type='revolute'>
        <pose relative_to='lf_hip_link'>0 0.0955 0 0 -0 0</pose>
        <parent>lf_hip_link</parent>
        <child>lf_upper_leg_link</child>
        <axis>
          <xyz>0 1 0</xyz>
          <limit>
            <lower>-1.5708</lower>
            <upper>3.4907</upper>
            <effort>23.7</effort>
            <velocity>30.1</velocity>
          </limit>
          <dynamics>
            <damping>0.01</damping>
            <friction>0.2</friction>
            <spring_reference>0</spring_reference>
            <spring_stiffness>0</spring_stiffness>
          </dynamics>
        </axis>
      </joint>
      <link name='lf_upper_leg_link'>
        <pose relative_to='lf_upper_leg_joint'>0 0 0 0 -0 0</pose>
        <inertial>
          <pose>-0.00374 -0.0223 -0.0327 0 -0 0</pose>
          <mass>1.152</mass>
          <inertia>
            <ixx>0.00584</ixx>
            <ixy>8.72e-05</ixy>
            <ixz>-0.000289</ixz>
            <iyy>0.0058</iyy>
            <iyz>0.000808</iyz>
            <izz>0.00103</izz>
          </inertia>
        </inertial>
        <collision name='lf_upper_leg_link_collision'>
          <pose>0 0 -0.1065 3.14159 1.57079 3.14159</pose>
          <geometry>
            <box>
              <size>0.213 0.0245 0.034</size>
            </box>
          </geometry>
          <surface>
            <contact>
              <ode>
                <kp>10000</kp>
                <kd>1</kd>
              </ode>
            </contact>
            <friction>
              <ode>
                <mu>0.2</mu>
                <mu2>0.2</mu2>
              </ode>
              <torsional>
                <ode/>
              </torsional>
            </friction>
            <bounce/>
          </surface>
          <max_contacts>10</max_contacts>
        </collision>
        <visual name='lf_upper_leg_link_visual'>
          <pose>0 0 0 0 -0 0</pose>
          <geometry>
            <mesh>
              <scale>1 1 1</scale>
              <uri>file:///usr/app/comp0244_ws/comp0244-go2/install/go2_description/share/go2_description/meshes/thigh.dae</uri>
            </mesh>
          </geometry>
        </visual>
        <self_collide>1</self_collide>
        <enable_wind>0</enable_wind>
        <kinematic>0</kinematic>
      </link>
      <joint name='lf_lower_leg_joint' type='revolute'>
        <pose relative_to='lf_upper_leg_link'>0 0 -0.213 0 -0 0</pose>
        <parent>lf_upper_leg_link</parent>
        <child>lf_lower_leg_link</child>
        <axis>
          <xyz>0 1 0</xyz>
          <limit>
            <lower>-2.7227</lower>
            <upper>-0.83776</upper>
            <effort>35.55</effort>
            <velocity>20.06</velocity>
          </limit>
          <dynamics>
            <damping>0.01</damping>
            <friction>0.2</friction>
            <spring_reference>0</spring_reference>
            <spring_stiffness>0</spring_stiffness>
          </dynamics>
        </axis>
      </joint>
      <link name='lf_lower_leg_link'>
        <pose relative_to='lf_lower_leg_joint'>0 0 0 0 -0 0</pose>
        <inertial>
          <pose>0.003944 -0.000702 -0.142477 0 -0 0</pose>
          <mass>0.214</mass>
          <inertia>
            <ixx>0.00150432</ixx>
            <ixy>5.70698e-07</ixy>
            <ixz>-5.98808e-06</ixz>
            <iyy>0.00152557</iyy>
            <iyz>1.24056e-05</iyz>
            <izz>4.38377e-05</izz>
          </inertia>
        </inertial>
        <collision name='lf_lower_leg_link_collision'>
          <pose>0 0 -0.1065 3.14159 1.57079 3.14159</pose>
          <geometry>
            <box>
              <size>0.213 0.016 0.016</size>
            </box>
          </geometry>
          <surface>
            <contact>
              <ode/>
            </contact>
            <friction>
              <ode>
                <mu>0.2</mu>
                <mu2>0.2</mu2>
              </ode>
              <torsional>
                <ode/>
              </torsional>
            </friction>
            <bounce/>
          </surface>
          <max_contacts>10</max_contacts>
        </collision>
        <collision name='lf_lower_leg_link_fixed_joint_lump__lf_foot_link_collision_1'>
          <pose>0 0 -0.213 0 -0 0</pose>
          <geometry>
            <sphere>
              <radius>0.02</radius>
            </sphere>
          </geometry>
          <surface>
            <contact>
              <ode>
                <kp>10000</kp>
                <kd>1</kd>
              </ode>
            </contact>
            <friction>
              <ode>
                <mu>0.6</mu>
                <mu2>0.6</mu2>
              </ode>
              <torsional>
                <ode/>
              </torsional>
            </friction>
            <bounce/>
          </surface>
          <max_contacts>10</max_contacts>
        </collision>
        <visual name='lf_lower_leg_link_visual'>
          <pose>0 0 0 0 -0 0</pose>
          <geometry>
            <mesh>
              <scale>1 1 1</scale>
              <uri>file:///usr/app/comp0244_ws/comp0244-go2/install/go2_description/share/go2_description/meshes/calf.dae</uri>
            </mesh>
          </geometry>
        </visual>
        <visual name='lf_lower_leg_link_fixed_joint_lump__lf_foot_link_visual_1'>
          <pose>0 0 -0.213 0 -0 0</pose>
          <geometry>
            <sphere>
              <radius>0.01</radius>
            </sphere>
          </geometry>
        </visual>
        <self_collide>1</self_collide>
        <self_collide>1</self_collide>
        <enable_wind>0</enable_wind>
        <kinematic>0</kinematic>
      </link>
      <joint name='lh_hip_joint' type='revolute'>
        <pose relative_to='base_link'>-0.1934 0.0465 0 0 -0 0</pose>
        <parent>base_link</parent>
        <child>lh_hip_link</child>
        <axis>
          <xyz>1 0 0</xyz>
          <limit>
            <lower>-1.0472</lower>
            <upper>1.0472</upper>
            <effort>23.7</effort>
            <velocity>30.1</velocity>
          </limit>
          <dynamics>
            <damping>0.01</damping>
            <friction>0.2</friction>
            <spring_reference>0</spring_reference>
            <spring_stiffness>0</spring_stiffness>
          </dynamics>
        </axis>
      </joint>
      <link name='lh_hip_link'>
        <pose relative_to='lh_hip_joint'>0 0 0 0 -0 0</pose>
        <inertial>
          <pose>0.0054 0.00194 -0.000105 0 -0 0</pose>
          <mass>0.678</mass>
          <inertia>
            <ixx>0.00048</ixx>
            <ixy>3.01e-06</ixy>
            <ixz>-1.11e-06</ixz>
            <iyy>0.000884</iyy>
            <iyz>-1.42e-06</iyz>
            <izz>0.000596</izz>
          </inertia>
        </inertial>
        <collision name='lh_hip_link_collision'>
          <pose>0 0.0955 0 1.5708 -0 0</pose>
          <geometry>
            <cylinder>
              <length>0.04</length>
              <radius>0.046</radius>
            </cylinder>
          </geometry>
          <max_contacts>10</max_contacts>
          <surface>
            <contact>
              <ode/>
            </contact>
            <bounce/>
            <friction>
              <torsional>
                <ode/>
              </torsional>
              <ode/>
            </friction>
          </surface>
        </collision>
        <visual name='lh_hip_link_visual'>
          <pose>0 0 0 3.14159 -0 3.14159</pose>
          <geometry>
            <mesh>
              <scale>1 1 1</scale>
              <uri>file:///usr/app/comp0244_ws/comp0244-go2/install/go2_description/share/go2_description/meshes/hip.dae</uri>
            </mesh>
          </geometry>
        </visual>
        <self_collide>0</self_collide>
        <enable_wind>0</enable_wind>
        <kinematic>0</kinematic>
      </link>
      <joint name='lh_upper_leg_joint' type='revolute'>
        <pose relative_to='lh_hip_link'>0 0.0955 0 0 -0 0</pose>
        <parent>lh_hip_link</parent>
        <child>lh_upper_leg_link</child>
        <axis>
          <xyz>0 1 0</xyz>
          <limit>
            <lower>-1.5708</lower>
            <upper>3.4907</upper>
            <effort>23.7</effort>
            <velocity>30.1</velocity>
          </limit>
          <dynamics>
            <damping>0.01</damping>
            <friction>0.2</friction>
            <spring_reference>0</spring_reference>
            <spring_stiffness>0</spring_stiffness>
          </dynamics>
        </axis>
      </joint>
      <link name='lh_upper_leg_link'>
        <pose relative_to='lh_upper_leg_joint'>0 0 0 0 -0 0</pose>
        <inertial>
          <pose>-0.00374 -0.0223 -0.0327 0 -0 0</pose>
          <mass>1.152</mass>
          <inertia>
            <ixx>0.00584</ixx>
            <ixy>8.72e-05</ixy>
            <ixz>-0.000289</ixz>
            <iyy>0.0058</iyy>
            <iyz>0.000808</iyz>
            <izz>0.00103</izz>
          </inertia>
        </inertial>
        <collision name='lh_upper_leg_link_collision'>
          <pose>0 0 -0.1065 3.14159 1.57079 3.14159</pose>
          <geometry>
            <box>
              <size>0.213 0.0245 0.034</size>
            </box>
          </geometry>
          <surface>
            <contact>
              <ode>
                <kp>10000</kp>
                <kd>1</kd>
              </ode>
            </contact>
            <friction>
              <ode>
                <mu>0.2</mu>
                <mu2>0.2</mu2>
              </ode>
              <torsional>
                <ode/>
              </torsional>
            </friction>
            <bounce/>
          </surface>
          <max_contacts>10</max_contacts>
        </collision>
        <visual name='lh_upper_leg_link_visual'>
          <pose>0 0 0 0 -0 0</pose>
          <geometry>
            <mesh>
              <scale>1 1 1</scale>
              <uri>file:///usr/app/comp0244_ws/comp0244-go2/install/go2_description/share/go2_description/meshes/thigh.dae</uri>
            </mesh>
          </geometry>
        </visual>
        <self_collide>1</self_collide>
        <enable_wind>0</enable_wind>
        <kinematic>0</kinematic>
      </link>
      <joint name='lh_lower_leg_joint' type='revolute'>
        <pose relative_to='lh_upper_leg_link'>0 0 -0.213 0 -0 0</pose>
        <parent>lh_upper_leg_link</parent>
        <child>lh_lower_leg_link</child>
        <axis>
          <xyz>0 1 0</xyz>
          <limit>
            <lower>-2.7227</lower>
            <upper>-0.83776</upper>
            <effort>35.55</effort>
            <velocity>20.06</velocity>
          </limit>
          <dynamics>
            <damping>0.01</damping>
            <friction>0.2</friction>
            <spring_reference>0</spring_reference>
            <spring_stiffness>0</spring_stiffness>
          </dynamics>
        </axis>
      </joint>
      <link name='lh_lower_leg_link'>
        <pose relative_to='lh_lower_leg_joint'>0 0 0 0 -0 0</pose>
        <inertial>
          <pose>0.003944 -0.000702 -0.142477 0 -0 0</pose>
          <mass>0.214</mass>
          <inertia>
            <ixx>0.00150432</ixx>
            <ixy>5.70698e-07</ixy>
            <ixz>-5.98808e-06</ixz>
            <iyy>0.00152557</iyy>
            <iyz>1.24056e-05</iyz>
            <izz>4.38377e-05</izz>
          </inertia>
        </inertial>
        <collision name='lh_lower_leg_link_collision'>
          <pose>0 0 -0.1065 3.14159 1.57079 3.14159</pose>
          <geometry>
            <box>
              <size>0.213 0.016 0.016</size>
            </box>
          </geometry>
          <surface>
            <contact>
              <ode/>
            </contact>
            <friction>
              <ode>
                <mu>0.2</mu>
                <mu2>0.2</mu2>
              </ode>
              <torsional>
                <ode/>
              </torsional>
            </friction>
            <bounce/>
          </surface>
          <max_contacts>10</max_contacts>
        </collision>
        <collision name='lh_lower_leg_link_fixed_joint_lump__lh_foot_link_collision_1'>
          <pose>0 0 -0.213 0 -0 0</pose>
          <geometry>
            <sphere>
              <radius>0.02</radius>
            </sphere>
          </geometry>
          <surface>
            <contact>
              <ode>
                <kp>10000</kp>
                <kd>1</kd>
              </ode>
            </contact>
            <friction>
              <ode>
                <mu>0.6</mu>
                <mu2>0.6</mu2>
              </ode>
              <torsional>
                <ode/>
              </torsional>
            </friction>
            <bounce/>
          </surface>
          <max_contacts>10</max_contacts>
        </collision>
        <visual name='lh_lower_leg_link_visual'>
          <pose>0 0 0 0 -0 0</pose>
          <geometry>
            <mesh>
              <scale>1 1 1</scale>
              <uri>file:///usr/app/comp0244_ws/comp0244-go2/install/go2_description/share/go2_description/meshes/calf.dae</uri>
            </mesh>
          </geometry>
        </visual>
        <visual name='lh_lower_leg_link_fixed_joint_lump__lh_foot_link_visual_1'>
          <pose>0 0 -0.213 0 -0 0</pose>
          <geometry>
            <sphere>
              <radius>0.01</radius>
            </sphere>
          </geometry>
        </visual>
        <self_collide>1</self_collide>
        <self_collide>1</self_collide>
        <enable_wind>0</enable_wind>
        <kinematic>0</kinematic>
      </link>
      <joint name='rf_hip_joint' type='revolute'>
        <pose relative_to='base_link'>0.1934 -0.0465 0 0 -0 0</pose>
        <parent>base_link</parent>
        <child>rf_hip_link</child>
        <axis>
          <xyz>1 0 0</xyz>
          <limit>
            <lower>-1.0472</lower>
            <upper>1.0472</upper>
            <effort>23.7</effort>
            <velocity>30.1</velocity>
          </limit>
          <dynamics>
            <damping>0.01</damping>
            <friction>0.2</friction>
            <spring_reference>0</spring_reference>
            <spring_stiffness>0</spring_stiffness>
          </dynamics>
        </axis>
      </joint>
      <link name='rf_hip_link'>
        <pose relative_to='rf_hip_joint'>0 0 0 0 -0 0</pose>
        <inertial>
          <pose>-0.0054 -0.00194 -0.000105 0 -0 0</pose>
          <mass>0.678</mass>
          <inertia>
            <ixx>0.00048</ixx>
            <ixy>3.01e-06</ixy>
            <ixz>1.11e-06</ixz>
            <iyy>0.000884</iyy>
            <iyz>1.42e-06</iyz>
            <izz>0.000596</izz>
          </inertia>
        </inertial>
        <collision name='rf_hip_link_collision'>
          <pose>0 -0.0955 0 1.5708 -0 0</pose>
          <geometry>
            <cylinder>
              <length>0.04</length>
              <radius>0.046</radius>
            </cylinder>
          </geometry>
          <max_contacts>10</max_contacts>
          <surface>
            <contact>
              <ode/>
            </contact>
            <bounce/>
            <friction>
              <torsional>
                <ode/>
              </torsional>
              <ode/>
            </friction>
          </surface>
        </collision>
        <visual name='rf_hip_link_visual'>
          <pose>0 0 0 3.14159 -0 0</pose>
          <geometry>
            <mesh>
              <scale>1 1 1</scale>
              <uri>file:///usr/app/comp0244_ws/comp0244-go2/install/go2_description/share/go2_description/meshes/hip.dae</uri>
            </mesh>
          </geometry>
        </visual>
        <self_collide>0</self_collide>
        <enable_wind>0</enable_wind>
        <kinematic>0</kinematic>
      </link>
      <joint name='rf_upper_leg_joint' type='revolute'>
        <pose relative_to='rf_hip_link'>0 -0.0955 0 0 -0 0</pose>
        <parent>rf_hip_link</parent>
        <child>rf_upper_leg_link</child>
        <axis>
          <xyz>0 1 0</xyz>
          <limit>
            <lower>-1.5708</lower>
            <upper>3.4907</upper>
            <effort>23.7</effort>
            <velocity>30.1</velocity>
          </limit>
          <dynamics>
            <damping>0.01</damping>
            <friction>0.2</friction>
            <spring_reference>0</spring_reference>
            <spring_stiffness>0</spring_stiffness>
          </dynamics>
        </axis>
      </joint>
      <link name='rf_upper_leg_link'>
        <pose relative_to='rf_upper_leg_joint'>0 0 0 0 -0 0</pose>
        <inertial>
          <pose>-0.00374 0.0223 -0.0327 0 -0 0</pose>
          <mass>1.152</mass>
          <inertia>
            <ixx>0.00584</ixx>
            <ixy>-8.72e-05</ixy>
            <ixz>-0.000289</ixz>
            <iyy>0.0058</iyy>
            <iyz>-0.000808</iyz>
            <izz>0.00103</izz>
          </inertia>
        </inertial>
        <collision name='rf_upper_leg_link_collision'>
          <pose>0 0 -0.1065 3.14159 1.57079 3.14159</pose>
          <geometry>
            <box>
              <size>0.213 0.0245 0.034</size>
            </box>
          </geometry>
          <surface>
            <contact>
              <ode>
                <kp>10000</kp>
                <kd>1</kd>
              </ode>
            </contact>
            <friction>
              <ode>
                <mu>0.2</mu>
                <mu2>0.2</mu2>
              </ode>
              <torsional>
                <ode/>
              </torsional>
            </friction>
            <bounce/>
          </surface>
          <max_contacts>10</max_contacts>
        </collision>
        <visual name='rf_upper_leg_link_visual'>
          <pose>0 0 0 0 -0 0</pose>
          <geometry>
            <mesh>
              <scale>1 1 1</scale>
              <uri>file:///usr/app/comp0244_ws/comp0244-go2/install/go2_description/share/go2_description/meshes/thigh_mirror.dae</uri>
            </mesh>
          </geometry>
        </visual>
        <self_collide>1</self_collide>
        <enable_wind>0</enable_wind>
        <kinematic>0</kinematic>
      </link>
      <joint name='rf_lower_leg_joint' type='revolute'>
        <pose relative_to='rf_upper_leg_link'>0 0 -0.213 0 -0 0</pose>
        <parent>rf_upper_leg_link</parent>
        <child>rf_lower_leg_link</child>
        <axis>
          <xyz>0 1 0</xyz>
          <limit>
            <lower>-2.7227</lower>
            <upper>-0.83776</upper>
            <effort>35.55</effort>
            <velocity>20.06</velocity>
          </limit>
          <dynamics>
            <damping>0.01</damping>
            <friction>0.2</friction>
            <spring_reference>0</spring_reference>
            <spring_stiffness>0</spring_stiffness>
          </dynamics>
        </axis>
      </joint>
      <link name='rf_lower_leg_link'>
        <pose relative_to='rf_lower_leg_joint'>0 0 0 0 -0 0</pose>
        <inertial>
          <pose>0.003944 -0.000702 -0.142477 0 -0 0</pose>
          <mass>0.214</mass>
          <inertia>
            <ixx>0.00150432</ixx>
            <ixy>5.70698e-07</ixy>
            <ixz>-5.98808e-06</ixz>
            <iyy>0.00152557</iyy>
            <iyz>1.24056e-05</iyz>
            <izz>4.38377e-05</izz>
          </inertia>
        </inertial>
        <collision name='rf_lower_leg_link_collision'>
          <pose>0 0 -0.1065 3.14159 1.57079 3.14159</pose>
          <geometry>
            <box>
              <size>0.213 0.016 0.016</size>
            </box>
          </geometry>
          <surface>
            <contact>
              <ode/>
            </contact>
            <friction>
              <ode>
                <mu>0.2</mu>
                <mu2>0.2</mu2>
              </ode>
              <torsional>
                <ode/>
              </torsional>
            </friction>
            <bounce/>
          </surface>
          <max_contacts>10</max_contacts>
        </collision>
        <collision name='rf_lower_leg_link_fixed_joint_lump__rf_foot_link_collision_1'>
          <pose>0 0 -0.213 0 -0 0</pose>
          <geometry>
            <sphere>
              <radius>0.02</radius>
            </sphere>
          </geometry>
          <surface>
            <contact>
              <ode>
                <kp>10000</kp>
                <kd>1</kd>
              </ode>
            </contact>
            <friction>
              <ode>
                <mu>0.6</mu>
                <mu2>0.6</mu2>
              </ode>
              <torsional>
                <ode/>
              </torsional>
            </friction>
            <bounce/>
          </surface>
          <max_contacts>10</max_contacts>
        </collision>
        <visual name='rf_lower_leg_link_visual'>
          <pose>0 0 0 0 -0 0</pose>
          <geometry>
            <mesh>
              <scale>1 1 1</scale>
              <uri>file:///usr/app/comp0244_ws/comp0244-go2/install/go2_description/share/go2_description/meshes/calf.dae</uri>
            </mesh>
          </geometry>
        </visual>
        <visual name='rf_lower_leg_link_fixed_joint_lump__rf_foot_link_visual_1'>
          <pose>0 0 -0.213 0 -0 0</pose>
          <geometry>
            <sphere>
              <radius>0.01</radius>
            </sphere>
          </geometry>
        </visual>
        <self_collide>1</self_collide>
        <self_collide>1</self_collide>
        <enable_wind>0</enable_wind>
        <kinematic>0</kinematic>
      </link>
      <joint name='rh_hip_joint' type='revolute'>
        <pose relative_to='base_link'>-0.1934 -0.0465 0 0 -0 0</pose>
        <parent>base_link</parent>
        <child>rh_hip_link</child>
        <axis>
          <xyz>1 0 0</xyz>
          <limit>
            <lower>-1.0472</lower>
            <upper>1.0472</upper>
            <effort>23.7</effort>
            <velocity>30.1</velocity>
          </limit>
          <dynamics>
            <damping>0.01</damping>
            <friction>0.2</friction>
            <spring_reference>0</spring_reference>
            <spring_stiffness>0</spring_stiffness>
          </dynamics>
        </axis>
      </joint>
      <link name='rh_hip_link'>
        <pose relative_to='rh_hip_joint'>0 0 0 0 -0 0</pose>
        <inertial>
          <pose>0.0054 -0.00194 -0.000105 0 -0 0</pose>
          <mass>0.678</mass>
          <inertia>
            <ixx>0.00048</ixx>
            <ixy>-3.01e-06</ixy>
            <ixz>-1.11e-06</ixz>
            <iyy>0.000884</iyy>
            <iyz>1.42e-06</iyz>
            <izz>0.000596</izz>
          </inertia>
        </inertial>
        <collision name='rh_hip_link_collision'>
          <pose>0 -0.0955 0 1.5708 -0 0</pose>
          <geometry>
            <cylinder>
              <length>0.04</length>
              <radius>0.046</radius>
            </cylinder>
          </geometry>
          <max_contacts>10</max_contacts>
          <surface>
            <contact>
              <ode/>
            </contact>
            <bounce/>
            <friction>
              <torsional>
                <ode/>
              </torsional>
              <ode/>
            </friction>
          </surface>
        </collision>
        <visual name='rh_hip_link_visual'>
          <pose>0 0 0 0 -0 3.14159</pose>
          <geometry>
            <mesh>
              <scale>1 1 1</scale>
              <uri>file:///usr/app/comp0244_ws/comp0244-go2/install/go2_description/share/go2_description/meshes/hip.dae</uri>
            </mesh>
          </geometry>
        </visual>
        <self_collide>0</self_collide>
        <enable_wind>0</enable_wind>
        <kinematic>0</kinematic>
      </link>
      <joint name='rh_upper_leg_joint' type='revolute'>
        <pose relative_to='rh_hip_link'>0 -0.0955 0 0 -0 0</pose>
        <parent>rh_hip_link</parent>
        <child>rh_upper_leg_link</child>
        <axis>
          <xyz>0 1 0</xyz>
          <limit>
            <lower>-1.5708</lower>
            <upper>3.4907</upper>
            <effort>23.7</effort>
            <velocity>30.1</velocity>
          </limit>
          <dynamics>
            <damping>0.01</damping>
            <friction>0.2</friction>
            <spring_reference>0</spring_reference>
            <spring_stiffness>0</spring_stiffness>
          </dynamics>
        </axis>
      </joint>
      <link name='rh_upper_leg_link'>
        <pose relative_to='rh_upper_leg_joint'>0 0 0 0 -0 0</pose>
        <inertial>
          <pose>-0.00374 0.0223 -0.0327 0 -0 0</pose>
          <mass>1.152</mass>
          <inertia>
            <ixx>0.00584</ixx>
            <ixy>-8.72e-05</ixy>
            <ixz>-0.000289</ixz>
            <iyy>0.0058</iyy>
            <iyz>-0.000808</iyz>
            <izz>0.00103</izz>
          </inertia>
        </inertial>
        <collision name='rh_upper_leg_link_collision'>
          <pose>0 0 -0.1065 3.14159 1.57079 3.14159</pose>
          <geometry>
            <box>
              <size>0.213 0.0245 0.034</size>
            </box>
          </geometry>
          <surface>
            <contact>
              <ode>
                <kp>10000</kp>
                <kd>1</kd>
              </ode>
            </contact>
            <friction>
              <ode>
                <mu>0.2</mu>
                <mu2>0.2</mu2>
              </ode>
              <torsional>
                <ode/>
              </torsional>
            </friction>
            <bounce/>
          </surface>
          <max_contacts>10</max_contacts>
        </collision>
        <visual name='rh_upper_leg_link_visual'>
          <pose>0 0 0 0 -0 0</pose>
          <geometry>
            <mesh>
              <scale>1 1 1</scale>
              <uri>file:///usr/app/comp0244_ws/comp0244-go2/install/go2_description/share/go2_description/meshes/thigh_mirror.dae</uri>
            </mesh>
          </geometry>
        </visual>
        <self_collide>1</self_collide>
        <enable_wind>0</enable_wind>
        <kinematic>0</kinematic>
      </link>
      <joint name='rh_lower_leg_joint' type='revolute'>
        <pose relative_to='rh_upper_leg_link'>0 0 -0.213 0 -0 0</pose>
        <parent>rh_upper_leg_link</parent>
        <child>rh_lower_leg_link</child>
        <axis>
          <xyz>0 1 0</xyz>
          <limit>
            <lower>-2.7227</lower>
            <upper>-0.83776</upper>
            <effort>35.55</effort>
            <velocity>20.06</velocity>
          </limit>
          <dynamics>
            <damping>0.01</damping>
            <friction>0.2</friction>
            <spring_reference>0</spring_reference>
            <spring_stiffness>0</spring_stiffness>
          </dynamics>
        </axis>
      </joint>
      <link name='rh_lower_leg_link'>
        <pose relative_to='rh_lower_leg_joint'>0 0 0 0 -0 0</pose>
        <inertial>
          <pose>0.003944 -0.000702 -0.142477 0 -0 0</pose>
          <mass>0.214</mass>
          <inertia>
            <ixx>0.00150432</ixx>
            <ixy>5.70698e-07</ixy>
            <ixz>-5.98808e-06</ixz>
            <iyy>0.00152557</iyy>
            <iyz>1.24056e-05</iyz>
            <izz>4.38377e-05</izz>
          </inertia>
        </inertial>
        <collision name='rh_lower_leg_link_collision'>
          <pose>0 0 -0.1065 3.14159 1.57079 3.14159</pose>
          <geometry>
            <box>
              <size>0.213 0.016 0.016</size>
            </box>
          </geometry>
          <surface>
            <contact>
              <ode/>
            </contact>
            <friction>
              <ode>
                <mu>0.2</mu>
                <mu2>0.2</mu2>
              </ode>
              <torsional>
                <ode/>
              </torsional>
            </friction>
            <bounce/>
          </surface>
          <max_contacts>10</max_contacts>
        </collision>
        <collision name='rh_lower_leg_link_fixed_joint_lump__rh_foot_link_collision_1'>
          <pose>0 0 -0.213 0 -0 0</pose>
          <geometry>
            <sphere>
              <radius>0.02</radius>
            </sphere>
          </geometry>
          <surface>
            <contact>
              <ode>
                <kp>10000</kp>
                <kd>1</kd>
              </ode>
            </contact>
            <friction>
              <ode>
                <mu>0.6</mu>
                <mu2>0.6</mu2>
              </ode>
              <torsional>
                <ode/>
              </torsional>
            </friction>
            <bounce/>
          </surface>
          <max_contacts>10</max_contacts>
        </collision>
        <visual name='rh_lower_leg_link_visual'>
          <pose>0 0 0 0 -0 0</pose>
          <geometry>
            <mesh>
              <scale>1 1 1</scale>
              <uri>file:///usr/app/comp0244_ws/comp0244-go2/install/go2_description/share/go2_description/meshes/calf.dae</uri>
            </mesh>
          </geometry>
        </visual>
        <visual name='rh_lower_leg_link_fixed_joint_lump__rh_foot_link_visual_1'>
          <pose>0 0 -0.213 0 -0 0</pose>
          <geometry>
            <sphere>
              <radius>0.01</radius>
            </sphere>
          </geometry>
        </visual>
        <self_collide>1</self_collide>
        <self_collide>1</self_collide>
        <enable_wind>0</enable_wind>
        <kinematic>0</kinematic>
      </link>
      <plugin name='p3d_base_controller' filename='libgazebo_ros_p3d.so'>
        <ros>
          <remapping>odom:=odom/ground_truth</remapping>
        </ros>
        <body_name>base_link</body_name>
        <frame_name>world</frame_name>
        <update_rate>10.0</update_rate>
        <xyz_offset>0 0 0</xyz_offset>
        <rpy_offset>0 0 0</rpy_offset>
        <gaussian_noise>0.01</gaussian_noise>
      </plugin>
      <static>0</static>
      <plugin name='gazebo_ros2_control' filename='libgazebo_ros2_control.so'>
        <parameters>/usr/app/comp0244_ws/comp0244-go2/install/go2_description/share/go2_description/config/ros_control/ros_control.yaml</parameters>
      </plugin>
      <pose>0 -3 0.275 0 -0 1.57</pose>
    </model>
    <model name='unit_box'>
      <pose>-2.32894 1.71582 0.5 0 -0 0</pose>
      <link name='link'>
        <inertial>
          <mass>1</mass>
          <inertia>
            <ixx>0.166667</ixx>
            <ixy>0</ixy>
            <ixz>0</ixz>
            <iyy>0.166667</iyy>
            <iyz>0</iyz>
            <izz>0.166667</izz>
          </inertia>
          <pose>0 0 0 0 -0 0</pose>
        </inertial>
        <collision name='collision'>
          <geometry>
            <box>
              <size>1 0.239996 1</size>
            </box>
          </geometry>
          <max_contacts>10</max_contacts>
          <surface>
            <contact>
              <ode/>
            </contact>
            <bounce/>
            <friction>
              <torsional>
                <ode/>
              </torsional>
              <ode/>
            </friction>
          </surface>
        </collision>
        <visual name='visual'>
          <geometry>
            <box>
              <size>1 0.239996 1</size>
            </box>
          </geometry>
          <material>
            <script>
              <name>Gazebo/Grey</name>
              <uri>file://media/materials/scripts/gazebo.material</uri>
            </script>
          </material>
        </visual>
        <self_collide>0</self_collide>
        <enable_wind>0</enable_wind>
        <kinematic>0</kinematic>
      </link>
    </model>
    <model name='unit_box_0'>
      <pose>-3.40975 1.864 0.5 0 -0 0</pose>
      <link name='link'>
        <inertial>
          <mass>1</mass>
          <inertia>
            <ixx>0.166667</ixx>
            <ixy>0</ixy>
            <ixz>0</ixz>
            <iyy>0.166667</iyy>
            <iyz>0</iyz>
            <izz>0.166667</izz>
          </inertia>
          <pose>0 0 0 0 -0 0</pose>
        </inertial>
        <collision name='collision'>
          <geometry>
            <box>
              <size>1 1 1</size>
            </box>
          </geometry>
          <max_contacts>10</max_contacts>
          <surface>
            <contact>
              <ode/>
            </contact>
            <bounce/>
            <friction>
              <torsional>
                <ode/>
              </torsional>
              <ode/>
            </friction>
          </surface>
        </collision>
        <visual name='visual'>
          <geometry>
            <box>
              <size>1 1 1</size>
            </box>
          </geometry>
          <material>
            <script>
              <name>Gazebo/Grey</name>
              <uri>file://media/materials/scripts/gazebo.material</uri>
            </script>
          </material>
        </visual>
        <self_collide>0</self_collide>
        <enable_wind>0</enable_wind>
        <kinematic>0</kinematic>
      </link>
    </model>
    <model name='unit_cylinder'>
      <pose>3.06224 2.07978 0.5 0 -0 0</pose>
      <link name='link'>
        <inertial>
          <mass>1</mass>
          <inertia>
            <ixx>0.145833</ixx>
            <ixy>0</ixy>
            <ixz>0</ixz>
            <iyy>0.145833</iyy>
            <iyz>0</iyz>
            <izz>0.125</izz>
          </inertia>
          <pose>0 0 0 0 -0 0</pose>
        </inertial>
        <collision name='collision'>
          <geometry>
            <cylinder>
              <radius>0.5</radius>
              <length>1</length>
            </cylinder>
          </geometry>
          <max_contacts>10</max_contacts>
          <surface>
            <contact>
              <ode/>
            </contact>
            <bounce/>
            <friction>
              <torsional>
                <ode/>
              </torsional>
              <ode/>
            </friction>
          </surface>
        </collision>
        <visual name='visual'>
          <geometry>
            <cylinder>
              <radius>0.5</radius>
              <length>1</length>
            </cylinder>
          </geometry>
          <material>
            <script>
              <name>Gazebo/Grey</name>
              <uri>file://media/materials/scripts/gazebo.material</uri>
            </script>
          </material>
        </visual>
        <self_collide>0</self_collide>
        <enable_wind>0</enable_wind>
        <kinematic>0</kinematic>
      </link>
    </model>
    <model name='unit_sphere_0'>
      <pose>3.52059 3.30513 0.5 0 -0 0</pose>
      <link name='link'>
        <inertial>
          <mass>1</mass>
          <inertia>
            <ixx>0.1</ixx>
            <ixy>0</ixy>
            <ixz>0</ixz>
            <iyy>0.1</iyy>
            <iyz>0</iyz>
            <izz>0.1</izz>
          </inertia>
          <pose>0 0 0 0 -0 0</pose>
        </inertial>
        <collision name='collision'>
          <geometry>
            <sphere>
              <radius>0.5</radius>
            </sphere>
          </geometry>
          <max_contacts>10</max_contacts>
          <surface>
            <contact>
              <ode/>
            </contact>
            <bounce/>
            <friction>
              <torsional>
                <ode/>
              </torsional>
              <ode/>
            </friction>
          </surface>
        </collision>
        <visual name='visual'>
          <geometry>
            <sphere>
              <radius>0.5</radius>
            </sphere>
          </geometry>
          <material>
            <script>
              <name>Gazebo/Grey</name>
              <uri>file://media/materials/scripts/gazebo.material</uri>
            </script>
          </material>
        </visual>
        <self_collide>0</self_collide>
        <enable_wind>0</enable_wind>
        <kinematic>0</kinematic>
      </link>
    </model>
  </world>
</sdf>
